Workbook
Name Slicer_c: #N/A

Sheet S1
A1: Fr | B1: Notes | C1: Keep | D1: Cumulative | E1: Sentences for Anki
A2: j'ai | B2: track 4 | D2: =IF(C2="x",COUNTA($C$2:C2),".") -> . | E2: =IF(C2="x",A2,"---") -> --- | G2: 1 | H2: j'ai invité un ami
A3: invité | D3: =IF(C3="x",COUNTA($C$2:C3),".") -> . | E3: =IF(C3="x",A3,"---") -> --- | G3: 2 | H3: tu as invite un ami
A4: j'ai invité | D4: =IF(C4="x",COUNTA($C$2:C4),".") -> . | E4: =IF(C4="x",A4,"---") -> --- | G4: 3 | H4: as-tu invite un ami?
A5: un ami | B5: -in/-un sulky sound | D5: =IF(C5="x",COUNTA($C$2:C5),".") -> . | E5: =IF(C5="x",A5,"---") -> --- | G5: 4 | H5: tu as invite un ami?
A6: j'ai invité un ami | C6: x | D6: =IF(C6="x",COUNTA($C$2:C6),".") -> 1 | E6: =IF(C6="x",A6,"---") -> j'ai invité un ami | G6: 5 | H6: j'ai confirme le meeting avec Ben
A7: j'ai invité Ben | D7: =IF(C7="x",COUNTA($C$2:C7),".") -> . | E7: =IF(C7="x",A7,"---") -> --- | G7: 6 | H7: j'ai visite Hanoi avec un ami
A8: tu as | B8: you have to forget things | D8: =IF(C8="x",COUNTA($C$2:C8),".") -> . | E8: =IF(C8="x",A8,"---") -> --- | G8: 7 | H8: j'ai prepare le café pour toi
A9: tu as invite | D9: =IF(C9="x",COUNTA($C$2:C9),".") -> . | E9: =IF(C9="x",A9,"---") -> --- | G9: 8 | H9: tu as prepare le café pour moi?
A10: tu as invite un ami | C10: x | D10: =IF(C10="x",COUNTA($C$2:C10),".") -> 2 | E10: =IF(C10="x",A10,"---") -> tu as invite un ami | G10: 9 | H10: tu as visite Hanoi (avec un ami)?
A11: as-tu invite un ami? | B11: 2/3 ways of forming questions | C11: x | D11: =IF(C11="x",COUNTA($C$2:C11),".") -> 3 | E11: =IF(C11="x",A11,"---") -> as-tu invite un ami? | G11: 10 | H11: tu as prepare le meeting avec Ben?
A12: tu as invite un ami? | C12: x | D12: =IF(C12="x",COUNTA($C$2:C12),".") -> 4 | E12: =IF(C12="x",A12,"---") -> tu as invite un ami?
A13: confirmer | D13: =IF(C13="x",COUNTA($C$2:C13),".") -> . | E13: =IF(C13="x",A13,"---") -> ---
A14: j'ai confirme | D14: =IF(C14="x",COUNTA($C$2:C14),".") -> . | E14: =IF(C14="x",A14,"---") -> ---
A15: le meeting | D15: =IF(C15="x",COUNTA($C$2:C15),".") -> . | E15: =IF(C15="x",A15,"---") -> ---
A16: j'ai confirme le meeting | D16: =IF(C16="x",COUNTA($C$2:C16),".") -> . | E16: =IF(C16="x",A16,"---") -> ---
A17: j'ai confirme le meeting avec Ben | C17: x | D17: =IF(C17="x",COUNTA($C$2:C17),".") -> 5 | E17: =IF(C17="x",A17,"---") -> j'ai confirme le meeting avec Ben
A18: visiter | D18: =IF(C18="x",COUNTA($C$2:C18),".") -> . | E18: =IF(C18="x",A18,"---") -> ---
A19: j'ai visite | D19: =IF(C19="x",COUNTA($C$2:C19),".") -> . | E19: =IF(C19="x",A19,"---") -> ---
A20: Hanoi | D20: =IF(C20="x",COUNTA($C$2:C20),".") -> . | E20: =IF(C20="x",A20,"---") -> ---
A21: avec un ami | D21: =IF(C21="x",COUNTA($C$2:C21),".") -> . | E21: =IF(C21="x",A21,"---") -> ---
A22: j'ai visite Hanoi avec un ami | C22: x | D22: =IF(C22="x",COUNTA($C$2:C22),".") -> 6 | E22: =IF(C22="x",A22,"---") -> j'ai visite Hanoi avec un ami
A23: preparer | D23: =IF(C23="x",COUNTA($C$2:C23),".") -> . | E23: =IF(C23="x",A23,"---") -> ---
A24: j'ai prepare | D24: =IF(C24="x",COUNTA($C$2:C24),".") -> . | E24: =IF(C24="x",A24,"---") -> ---
A25: le café | D25: =IF(C25="x",COUNTA($C$2:C25),".") -> . | E25: =IF(C25="x",A25,"---") -> ---
A26: pour toi | D26: =IF(C26="x",COUNTA($C$2:C26),".") -> . | E26: =IF(C26="x",A26,"---") -> ---
A27: j'ai prepare le café pour toi | B27: introducing a lot, but will review a lot, don't worry they'll stick eventually | C27: x | D27: =IF(C27="x",COUNTA($C$2:C27),".") -> 7 | E27: =IF(C27="x",A27,"---") -> j'ai prepare le café pour toi
A28: pour moi | D28: =IF(C28="x",COUNTA($C$2:C28),".") -> . | E28: =IF(C28="x",A28,"---") -> ---
A29: tu as prepare le café pour moi | D29: =IF(C29="x",COUNTA($C$2:C29),".") -> . | E29: =IF(C29="x",A29,"---") -> ---
A30: tu as prepare le café pour moi? | C30: x | D30: =IF(C30="x",COUNTA($C$2:C30),".") -> 8 | E30: =IF(C30="x",A30,"---") -> tu as prepare le café pour moi?
A31: tu as visite Hanoi (avec un ami)? | C31: x | D31: =IF(C31="x",COUNTA($C$2:C31),".") -> 9 | E31: =IF(C31="x",A31,"---") -> tu as visite Hanoi (avec un ami)?
A32: tu as prepare le meeting avec Ben? | C32: x | D32: =IF(C32="x",COUNTA($C$2:C32),".") -> 10 | E32: =IF(C32="x",A32,"---") -> tu as prepare le meeting avec Ben?

Sheet S2
A1: Fr | B1: Notes | C1: New Item | D1: Keep | E1: Cumulative
A2: reservé | B2: figure out from noun | E2: =IF(D2="x",COUNTA($D$2:D2),".") -> . | F2: =IF(D2="x",A2,"---") -> --- | H2: 1 | I2: j'ai reserve un table
A3: une table | B3: -able words for free! | E3: =IF(D3="x",COUNTA($D$2:D3),".") -> . | F3: =IF(D3="x",A3,"---") -> --- | H3: 2 | I3: tu as reserve un table?
A4: j'ai reserve un table | D4: x | E4: =IF(D4="x",COUNTA($D$2:D4),".") -> 1 | F4: =IF(D4="x",A4,"---") -> j'ai reserve un table | H4: 3 | I4: il a reserve un table
A5: tu as reserve un table? | B5: tu | D5: x | E5: =IF(D5="x",COUNTA($D$2:D5),".") -> 2 | F5: =IF(D5="x",A5,"---") -> tu as reserve un table? | H5: 4 | I5: elle a reserve un table
A6: il a reserve un table | C6: 3ps pp have | D6: x | E6: =IF(D6="x",COUNTA($D$2:D6),".") -> 3 | F6: =IF(D6="x",A6,"---") -> il a reserve un table | H6: 5 | I6: mon ami a prepare le café
A7: elle a reserve un table | D7: x | E7: =IF(D7="x",COUNTA($D$2:D7),".") -> 4 | F7: =IF(D7="x",A7,"---") -> elle a reserve un table | H7: 6 | I7: mon ami a visite Hanoi
A8: mon | C8: pos1 | E8: =IF(D8="x",COUNTA($D$2:D8),".") -> . | F8: =IF(D8="x",A8,"---") -> --- | H8: 7 | I8: mon ami a visite Hanoi et mon chat a visite Taipei
A9: mon ami | E9: =IF(D9="x",COUNTA($D$2:D9),".") -> . | F9: =IF(D9="x",A9,"---") -> --- | H9: 8 | I9: mon ami a prepare le café et mon chat a prepare le the
A10: mon ami a prepare le café | D10: x | E10: =IF(D10="x",COUNTA($D$2:D10),".") -> 5 | F10: =IF(D10="x",A10,"---") -> mon ami a prepare le café | H10: 9 | I10: il a prepare le café
A11: mon ami a visite Hanoi | D11: x | E11: =IF(D11="x",COUNTA($D$2:D11),".") -> 6 | F11: =IF(D11="x",A11,"---") -> mon ami a visite Hanoi | H11: 10 | I11: preparation
A12: chien | E12: =IF(D12="x",COUNTA($D$2:D12),".") -> . | F12: =IF(D12="x",A12,"---") -> --- | H12: 11 | I12: Invitation
A13: mon chien | E13: =IF(D13="x",COUNTA($D$2:D13),".") -> . | F13: =IF(D13="x",A13,"---") -> --- | H13: 12 | I13: reservation
A14: mon chien a visite Taipei | E14: =IF(D14="x",COUNTA($D$2:D14),".") -> . | F14: =IF(D14="x",A14,"---") -> --- | H14: 13 | I14: decoration
A15: mon ami a visite Hanoi et mon chat a visite Taipei | B15: et | D15: x | E15: =IF(D15="x",COUNTA($D$2:D15),".") -> 7 | F15: =IF(D15="x",A15,"---") -> mon ami a visite Hanoi et mon chat a visite Taipei | H15: 14 | I15: confirmation
A16: le the | E16: =IF(D16="x",COUNTA($D$2:D16),".") -> . | F16: =IF(D16="x",A16,"---") -> --- | H16: 15 | I16: j'ai reservé un table pour le diner
A17: mon ami a prepare le café et mon chat a prepare le the | B17: 3 tenses in one | D17: x | E17: =IF(D17="x",COUNTA($D$2:D17),".") -> 8 | F17: =IF(D17="x",A17,"---") -> mon ami a prepare le café et mon chat a prepare le the | H17: 16 | I17: j'ai invite un ami au restaurant
A18: il a prepare le café | B18: (13') | D18: x | E18: =IF(D18="x",COUNTA($D$2:D18),".") -> 9 | F18: =IF(D18="x",A18,"---") -> il a prepare le café | H18: 17 | I18: tu as invite ton ami au restaurant?
A19: preparation | B19: track 7. -ion nouns coming from French, you already know 1000+ | D19: x | E19: =IF(D19="x",COUNTA($D$2:D19),".") -> 10 | F19: =IF(D19="x",A19,"---") -> preparation | H19: 18 | I19: je voudrais preparer le diner
A20: -ation | E20: =IF(D20="x",COUNTA($D$2:D20),".") -> . | F20: =IF(D20="x",A20,"---") -> --- | H20: 19 | I20: je voudrais preparer le diner + parce que j'ai faim
A21: Invitation | B21: -in/-un sulky sound | D21: x | E21: =IF(D21="x",COUNTA($D$2:D21),".") -> 11 | F21: =IF(D21="x",A21,"---") -> Invitation | H21: 20 | I21: je voudrais preparer le café parce que j'ai soif
A22: reservation | D22: x | E22: =IF(D22="x",COUNTA($D$2:D22),".") -> 12 | F22: =IF(D22="x",A22,"---") -> reservation
A23: decoration | D23: x | E23: =IF(D23="x",COUNTA($D$2:D23),".") -> 13 | F23: =IF(D23="x",A23,"---") -> decoration
A24: confirmation | D24: x | E24: =IF(D24="x",COUNTA($D$2:D24),".") -> 14 | F24: =IF(D24="x",A24,"---") -> confirmation
A25: preparé | B25: even better, can make past tense from it by cutting -ation and add café é | E25: =IF(D25="x",COUNTA($D$2:D25),".") -> . | F25: =IF(D25="x",A25,"---") -> ---
A26: j'ai reservé | B26: careful with "j'ai" pronunciation | E26: =IF(D26="x",COUNTA($D$2:D26),".") -> . | F26: =IF(D26="x",A26,"---") -> ---
A27: j'ai reservé un table pour le diner | D27: x | E27: =IF(D27="x",COUNTA($D$2:D27),".") -> 15 | F27: =IF(D27="x",A27,"---") -> j'ai reservé un table pour le diner
A28: j'ai invite un ami au restaurant | D28: x | E28: =IF(D28="x",COUNTA($D$2:D28),".") -> 16 | F28: =IF(D28="x",A28,"---") -> j'ai invite un ami au restaurant
A29: ton | C29: pos 2s | E29: =IF(D29="x",COUNTA($D$2:D29),".") -> . | F29: =IF(D29="x",A29,"---") -> ---
A30: ton ami | E30: =IF(D30="x",COUNTA($D$2:D30),".") -> . | F30: =IF(D30="x",A30,"---") -> ---
A31: tu as invite ton ami au restaurant? | D31: x | E31: =IF(D31="x",COUNTA($D$2:D31),".") -> 17 | F31: =IF(D31="x",A31,"---") -> tu as invite ton ami au restaurant?
A32: preparer | B32: Infinitive: cut ation and add er, same pronunciation. (track 9?) | E32: =IF(D32="x",COUNTA($D$2:D32),".") -> . | F32: =IF(D32="x",A32,"---") -> ---
A33: je voudrais | E33: =IF(D33="x",COUNTA($D$2:D33),".") -> . | F33: =IF(D33="x",A33,"---") -> ---
A34: je voudrais preparer | E34: =IF(D34="x",COUNTA($D$2:D34),".") -> . | F34: =IF(D34="x",A34,"---") -> ---
A35: je voudrais preparer le diner | B35: same "é" | D35: x | E35: =IF(D35="x",COUNTA($D$2:D35),".") -> 18 | F35: =IF(D35="x",A35,"---") -> je voudrais preparer le diner
A36: j'ai faim | B36: "I have hunger" | E36: =IF(D36="x",COUNTA($D$2:D36),".") -> . | F36: =IF(D36="x",A36,"---") -> ---
A37: parce que | E37: =IF(D37="x",COUNTA($D$2:D37),".") -> . | F37: =IF(D37="x",A37,"---") -> ---
A38: je voudrais preparer le diner + parce que j'ai faim | D38: x | E38: =IF(D38="x",COUNTA($D$2:D38),".") -> 19 | F38: =IF(D38="x",A38,"---") -> je voudrais preparer le diner + parce que j'ai faim
A39: soif | E39: =IF(D39="x",COUNTA($D$2:D39),".") -> . | F39: =IF(D39="x",A39,"---") -> ---
A40: j'ai soif | E40: =IF(D40="x",COUNTA($D$2:D40),".") -> . | F40: =IF(D40="x",A40,"---") -> ---
...

Sheet S3
A1: Type | B1: Fr | C1: Notes | D1: New Item | E1: Keep | F1: Cumulative
A2: V | B2: Ce soir | F2: =IF(E2="x",COUNTA($E$2:E2),".") -> . | G2: =IF(E2="x",B2,"---") -> ---
A3: LV | B3: Je voudrais réserver pour ce soir | E3: x | F3: =IF(E3="x",COUNTA($E$2:E3),".") -> 1 | G3: =IF(E3="x",B3,"---") -> Je voudrais réserver pour ce soir
A4: LV | B4: Une personne | C4: from "person" | F4: =IF(E4="x",COUNTA($E$2:E4),".") -> . | G4: =IF(E4="x",B4,"---") -> ---
A5: P | B5: Deux | F5: =IF(E5="x",COUNTA($E$2:E5),".") -> . | G5: =IF(E5="x",B5,"---") -> ---
A6: LV | B6: Deux personnes | F6: =IF(E6="x",COUNTA($E$2:E6),".") -> . | G6: =IF(E6="x",B6,"---") -> ---
A7: PE | B7: Je voudrais réserver une table pour ce soir pour deux personnes | F7: =IF(E7="x",COUNTA($E$2:E7),".") -> . | G7: =IF(E7="x",B7,"---") -> ---
B8: J'ai réservé une table pour ce soir pour deux personnes | E8: x | F8: =IF(E8="x",COUNTA($E$2:E8),".") -> 2 | G8: =IF(E8="x",B8,"---") -> J'ai réservé une table pour ce soir pour deux personnes
A9: V | B9: Vous | C9: plural & politness | F9: =IF(E9="x",COUNTA($E$2:E9),".") -> . | G9: =IF(E9="x",B9,"---") -> ---
A10: V | B10: Voulez-vous | F10: =IF(E10="x",COUNTA($E$2:E10),".") -> . | G10: =IF(E10="x",B10,"---") -> ---
A11: C | B11: Voulez-vous reserver une table pour ce soir? | E11: x | F11: =IF(E11="x",COUNTA($E$2:E11),".") -> 3 | G11: =IF(E11="x",B11,"---") -> Voulez-vous reserver une table pour ce soir?
A12: C | B12: Voulez-vous visiter Hanoi? | C12: -> vous voulez | E12: x | F12: =IF(E12="x",COUNTA($E$2:E12),".") -> 4 | G12: =IF(E12="x",B12,"---") -> Voulez-vous visiter Hanoi? | J12: achievement #1
A13: V | B13: C'est | C13: it is. Still same sound as café e and -er | F13: =IF(E13="x",COUNTA($E$2:E13),".") -> . | G13: =IF(E13="x",B13,"---") -> ---
A14: V | B14: Typique | C14: track 12 ~42'. -ic & -cal -> -ique. Logique. | E14: x | F14: =IF(E14="x",COUNTA($E$2:E14),".") -> 5 | G14: =IF(E14="x",B14,"---") -> Typique | J14: clips or medley
A15: V | B15: Exotic | E15: x | F15: =IF(E15="x",COUNTA($E$2:E15),".") -> 6 | G15: =IF(E15="x",B15,"---") -> Exotic
B16: Politique | E16: x | F16: =IF(E16="x",COUNTA($E$2:E16),".") -> 7 | G16: =IF(E16="x",B16,"---") -> Politique
B17: Romantic | E17: x | F17: =IF(E17="x",COUNTA($E$2:E17),".") -> 8 | G17: =IF(E17="x",B17,"---") -> Romantic
B18: Pratique | E18: x | F18: =IF(E18="x",COUNTA($E$2:E18),".") -> 9 | G18: =IF(E18="x",B18,"---") -> Pratique
A19: P | B19: Parce que | E19: x | F19: =IF(E19="x",COUNTA($E$2:E19),".") -> 10 | G19: =IF(E19="x",B19,"---") -> Parce que
A20: PC | B20: Je voudrais visiter Paris parce que c'est exotique | E20: x | F20: =IF(E20="x",COUNTA($E$2:E20),".") -> 11 | G20: =IF(E20="x",B20,"---") -> Je voudrais visiter Paris parce que c'est exotique
A21: PC | B21: Est-ce que tu as preparé le café pour moi? | C21: (3) | E21: x | F21: =IF(E21="x",COUNTA($E$2:E21),".") -> 12 | G21: =IF(E21="x",B21,"---") -> Est-ce que tu as preparé le café pour moi?
A22: PC | B22: Est-ce que tu as confirmé le meeting avec Jean? | C22: Jean | E22: x | F22: =IF(E22="x",COUNTA($E$2:E22),".") -> 13 | G22: =IF(E22="x",B22,"---") -> Est-ce que tu as confirmé le meeting avec Jean?
A23: PC | B23: Est-ce que c'est pratique? | E23: x | F23: =IF(E23="x",COUNTA($E$2:E23),".") -> 14 | G23: =IF(E23="x",B23,"---") -> Est-ce que c'est pratique?
A24: V | B24: Aller | F24: =IF(E24="x",COUNTA($E$2:E24),".") -> . | G24: =IF(E24="x",B24,"---") -> ---
A25: C | B25: Je voudrais aller a Paris | C25: a = to | E25: x | F25: =IF(E25="x",COUNTA($E$2:E25),".") -> 15 | G25: =IF(E25="x",B25,"---") -> Je voudrais aller a Paris
A26: C | B26: Je voudrais aller a Paris, est-ce que c'est pratique? | F26: =IF(E26="x",COUNTA($E$2:E26),".") -> . | G26: =IF(E26="x",B26,"---") -> ---
A27: C | B27: Je voudrais aller au café, est-ce qu'il est typique? | E27: x | F27: =IF(E27="x",COUNTA($E$2:E27),".") -> 16 | G27: =IF(E27="x",B27,"---") -> Je voudrais aller au café, est-ce qu'il est typique?
A28: V | B28: Savoir | E28: x | F28: =IF(E28="x",COUNTA($E$2:E28),".") -> 17 | G28: =IF(E28="x",B28,"---") -> Savoir
A29: C | B29: Je voudrais savoir | F29: =IF(E29="x",COUNTA($E$2:E29),".") -> . | G29: =IF(E29="x",B29,"---") -> ---
A30: V | B30: Si | C30: c'est vs si | F30: =IF(E30="x",COUNTA($E$2:E30),".") -> . | G30: =IF(E30="x",B30,"---") -> ---
A31: C | B31: Je voudrais savoir si c'est typique | F31: =IF(E31="x",COUNTA($E$2:E31),".") -> . | G31: =IF(E31="x",B31,"---") -> ---
A32: C | B32: Je voudrais savoir si c'est pratique | E32: x | F32: =IF(E32="x",COUNTA($E$2:E32),".") -> 18 | G32: =IF(E32="x",B32,"---") -> Je voudrais savoir si c'est pratique
A33: V | B33: Mais | F33: =IF(E33="x",COUNTA($E$2:E33),".") -> . | G33: =IF(E33="x",B33,"---") -> ---
A34: C | B34: Je voudrais reserver une table, mais je voudrais savoir si c'est pratique | F34: =IF(E34="x",COUNTA($E$2:E34),".") -> . | G34: =IF(E34="x",B34,"---") -> ---
A35: C | B35: Voulez-vous reserver un table? Oui, mais je voudrais savoir si c'est pratique | E35: x | F35: =IF(E35="x",COUNTA($E$2:E35),".") -> 19 | G35: =IF(E35="x",B35,"---") -> Voulez-vous reserver un table? Oui, mais je voudrais savoir si c'est pratique
B36: Vous voulez | F36: =IF(E36="x",COUNTA($E$2:E36),".") -> . | G36: =IF(E36="x",B36,"---") -> ---
B37: Est-ce que vous voulez reserver un table? | E37: x | F37: =IF(E37="x",COUNTA($E$2:E37),".") -> 20 | G37: =IF(E37="x",B37,"---") -> Est-ce que vous voulez reserver un table?
B38: Est-ce que vous voulez reserver un table? Oui, mais je voudrais savoir si c'est pratique | F38: =IF(E38="x",COUNTA($E$2:E38),".") -> . | G38: =IF(E38="x",B38,"---") -> ---

Sheet S4^
A1: Type | B1: Fr | C1: Notes | D1: PN track start | E1: New Item | F1: Keep | G1: Cum.
A2: V | B2: Ce n'est pas | C2: Négation Sandwich vs ? -> must have a filling | F2: x | G2: =IF(F2="x",COUNTA($F$2:F2),".") -> 1 | H2: =IF(F2="x",B2,"---") -> Ce n'est pas
A3: V | B3: C'est pas | C3: one nég is enough, practice omitting the first one exclusively | F3: x | G3: =IF(F3="x",COUNTA($F$2:F3),".") -> 2 | H3: =IF(F3="x",B3,"---") -> C'est pas
A4: V | B4: Non, c'est pas pratique | F4: x | G4: =IF(F4="x",COUNTA($F$2:F4),".") -> 3 | H4: =IF(F4="x",B4,"---") -> Non, c'est pas pratique
B5: Je voudrais allez a Paris, mais c'est pas pratique | F5: x | G5: =IF(F5="x",COUNTA($F$2:F5),".") -> 4 | H5: =IF(F5="x",B5,"---") -> Je voudrais allez a Paris, mais c'est pas pratique
A6: V | B6: Pourquoi? | C6: "For what" | F6: x | G6: =IF(F6="x",COUNTA($F$2:F6),".") -> 5 | H6: =IF(F6="x",B6,"---") -> Pourquoi?
A7: C | B7: Pourquoi c'est pas pratique? | F7: x | G7: =IF(F7="x",COUNTA($F$2:F7),".") -> 6 | H7: =IF(F7="x",B7,"---") -> Pourquoi c'est pas pratique?
A8: C | B8: Je voudrais savoir pourquoi c'est pas pratique | F8: x | G8: =IF(F8="x",COUNTA($F$2:F8),".") -> 7 | H8: =IF(F8="x",B8,"---") -> Je voudrais savoir pourquoi c'est pas pratique
A9: C | B9: Pourquoi tu as preparé le diné? | F9: x | G9: =IF(F9="x",COUNTA($F$2:F9),".") -> 8 | H9: =IF(F9="x",B9,"---") -> Pourquoi tu as preparé le diné?
B10: Tu as préparé le diné? | C10: En Francais, c'est typique | G10: =IF(F10="x",COUNTA($F$2:F10),".") -> . | H10: =IF(F10="x",B10,"---") -> --- | K10: Est-ce que tu as confirmé le meeting avec Jean?
B11: Tu as préparé le café? | F11: x | G11: =IF(F11="x",COUNTA($F$2:F11),".") -> 9 | H11: =IF(F11="x",B11,"---") -> Tu as préparé le café?
B12: Oui, j'ai préparé le café | G12: =IF(F12="x",COUNTA($F$2:F12),".") -> . | H12: =IF(F12="x",B12,"---") -> ---
B13: Tu n'as pas préparé le café? | F13: x | G13: =IF(F13="x",COUNTA($F$2:F13),".") -> 10 | H13: =IF(F13="x",B13,"---") -> Tu n'as pas préparé le café?
B14: Tu as pas préparé le café? | F14: x | G14: =IF(F14="x",COUNTA($F$2:F14),".") -> 11 | H14: =IF(F14="x",B14,"---") -> Tu as pas préparé le café?
B15: Tu as -> tu n'as pas | C15: sandwich | G15: =IF(F15="x",COUNTA($F$2:F15),".") -> . | H15: =IF(F15="x",B15,"---") -> ---
B16: Tu as -> tu as pas | C16: sushi | G16: =IF(F16="x",COUNTA($F$2:F16),".") -> . | H16: =IF(F16="x",B16,"---") -> ---
B17: Je voudrais savoir pourquoi tu n'as pas préparé le café | F17: x | G17: =IF(F17="x",COUNTA($F$2:F17),".") -> 12 | H17: =IF(F17="x",B17,"---") -> Je voudrais savoir pourquoi tu n'as pas préparé le café
B18: J'ai faim, pourquoi tu as pas préparé le diné? | F18: x | G18: =IF(F18="x",COUNTA($F$2:F18),".") -> 13 | H18: =IF(F18="x",B18,"---") -> J'ai faim, pourquoi tu as pas préparé le diné?
B19: Je n'ai pas | C19: **easy to insert "jamais" here | G19: =IF(F19="x",COUNTA($F$2:F19),".") -> . | H19: =IF(F19="x",B19,"---") -> ---
B20: Je n'ai pas visité Paris | D20: 2_3 | F20: x | G20: =IF(F20="x",COUNTA($F$2:F20),".") -> 14 | H20: =IF(F20="x",B20,"---") -> Je n'ai pas visité Paris
B21: Je n'ai pas invité Jean au ciné(ma) | F21: x | G21: =IF(F21="x",COUNTA($F$2:F21),".") -> 15 | H21: =IF(F21="x",B21,"---") -> Je n'ai pas invité Jean au ciné(ma)
A22: V | B22: Désolé | F22: x | G22: =IF(F22="x",COUNTA($F$2:F22),".") -> 16 | H22: =IF(F22="x",B22,"---") -> Désolé
B23: J'ai pas préparé le café, désolé | F23: x | G23: =IF(F23="x",COUNTA($F$2:F23),".") -> 17 | H23: =IF(F23="x",B23,"---") -> J'ai pas préparé le café, désolé
B24: Désolé, mais j'ai pas préparé le café | F24: x | G24: =IF(F24="x",COUNTA($F$2:F24),".") -> 18 | H24: =IF(F24="x",B24,"---") -> Désolé, mais j'ai pas préparé le café
A25: V | B25: Français | C25: masc | F25: x | G25: =IF(F25="x",COUNTA($F$2:F25),".") -> 19 | H25: =IF(F25="x",B25,"---") -> Français
B26: Désolé, mais j'ai pas réservé une table au restau Français | C26: restau = restaurant | F26: x | G26: =IF(F26="x",COUNTA($F$2:F26),".") -> 20 | H26: =IF(F26="x",B26,"---") -> Désolé, mais j'ai pas réservé une table au restau Français

Sheet S5
A1: Type | B1: Fr | C1: Notes | D1: PN track start | E1: New Item | F1: Keep | G1: Cum.
B2: Je voudrais préparer le diné | D2: 2_4 | G2: =IF(F2="x",COUNTA($F$2:F2),".") -> . | H2: =IF(F2="x",B2,"---") -> ---
A3: ~V | B3: Le préparer | C3: prepare it | G3: =IF(F3="x",COUNTA($F$2:F3),".") -> . | H3: =IF(F3="x",B3,"---") -> ---
B4: Je voudrais le préparer | G4: =IF(F4="x",COUNTA($F$2:F4),".") -> . | H4: =IF(F4="x",B4,"---") -> ---
A5: V | B5: Je peux | G5: =IF(F5="x",COUNTA($F$2:F5),".") -> . | H5: =IF(F5="x",B5,"---") -> ---
B6: Je peux préparer le diné | G6: =IF(F6="x",COUNTA($F$2:F6),".") -> . | H6: =IF(F6="x",B6,"---") -> ---
B7: Je peux le préparer | G7: =IF(F7="x",COUNTA($F$2:F7),".") -> . | H7: =IF(F7="x",B7,"---") -> ---
B8: Il peux | G8: =IF(F8="x",COUNTA($F$2:F8),".") -> . | H8: =IF(F8="x",B8,"---") -> ---
B9: Elle peux | G9: =IF(F9="x",COUNTA($F$2:F9),".") -> . | H9: =IF(F9="x",B9,"---") -> ---
B10: Il peux le préparer | G10: =IF(F10="x",COUNTA($F$2:F10),".") -> . | H10: =IF(F10="x",B10,"---") -> ---
B11: Elle peux le manger | G11: =IF(F11="x",COUNTA($F$2:F11),".") -> . | H11: =IF(F11="x",B11,"---") -> ---
B12: Je peux, tu peux, il peux, elle peux | G12: =IF(F12="x",COUNTA($F$2:F12),".") -> . | H12: =IF(F12="x",B12,"---") -> ---
A13: V | B13: Faire | G13: =IF(F13="x",COUNTA($F$2:F13),".") -> . | H13: =IF(F13="x",B13,"---") -> ---
B14: Il peut le faire | G14: =IF(F14="x",COUNTA($F$2:F14),".") -> . | H14: =IF(F14="x",B14,"---") -> ---
A15: V | B15: Aujourd'hui | G15: =IF(F15="x",COUNTA($F$2:F15),".") -> . | H15: =IF(F15="x",B15,"---") -> ---
B16: Elle peut le faire aujourd'hui | G16: =IF(F16="x",COUNTA($F$2:F16),".") -> . | H16: =IF(F16="x",B16,"---") -> ---
B17: Elle peut le faire demain | G17: =IF(F17="x",COUNTA($F$2:F17),".") -> . | H17: =IF(F17="x",B17,"---") -> ---
B18: Elle ne peut pas | G18: =IF(F18="x",COUNTA($F$2:F18),".") -> . | H18: =IF(F18="x",B18,"---") -> ---
B19: Je peux pas | G19: =IF(F19="x",COUNTA($F$2:F19),".") -> . | H19: =IF(F19="x",B19,"---") -> ---
B20: Je peux pas le faire aujourd'hui | G20: =IF(F20="x",COUNTA($F$2:F20),".") -> . | H20: =IF(F20="x",B20,"---") -> ---
B21: Tu peux | D21: 2_5 | G21: =IF(F21="x",COUNTA($F$2:F21),".") -> . | H21: =IF(F21="x",B21,"---") -> ---
B22: Tu peux le faire demain | G22: =IF(F22="x",COUNTA($F$2:F22),".") -> . | H22: =IF(F22="x",B22,"---") -> ---
B23: Tu peux le faire demain? | G23: =IF(F23="x",COUNTA($F$2:F23),".") -> . | H23: =IF(F23="x",B23,"---") -> ---
B24: Est-que tu peux le faire aujourd'hui? | G24: =IF(F24="x",COUNTA($F$2:F24),".") -> . | H24: =IF(F24="x",B24,"---") -> ---
B25: Je peux le manger? | G25: =IF(F25="x",COUNTA($F$2:F25),".") -> . | H25: =IF(F25="x",B25,"---") -> ---
A26: V | B26: On | G26: =IF(F26="x",COUNTA($F$2:F26),".") -> . | H26: =IF(F26="x",B26,"---") -> ---
B27: On peut | G27: =IF(F27="x",COUNTA($F$2:F27),".") -> . | H27: =IF(F27="x",B27,"---") -> ---
B28: On peut le faire | G28: =IF(F28="x",COUNTA($F$2:F28),".") -> . | H28: =IF(F28="x",B28,"---") -> ---
A29: V | B29: Je peux pas le manger | G29: =IF(F29="x",COUNTA($F$2:F29),".") -> . | H29: =IF(F29="x",B29,"---") -> ---
B30: Je peux pas le faire | G30: =IF(F30="x",COUNTA($F$2:F30),".") -> . | H30: =IF(F30="x",B30,"---") -> ---
B31: Je peux pas le faire aujourd'hui | D31: 2_6~ | G31: =IF(F31="x",COUNTA($F$2:F31),".") -> . | H31: =IF(F31="x",B31,"---") -> ---
A32: V | B32: Comprendre | G32: =IF(F32="x",COUNTA($F$2:F32),".") -> . | H32: =IF(F32="x",B32,"---") -> ---
B33: Je peux comprendre | G33: =IF(F33="x",COUNTA($F$2:F33),".") -> . | H33: =IF(F33="x",B33,"---") -> ---

Sheet S6
A1: Type | B1: Fr | C1: Notes | D1: PN track start | E1: New Item | F1: Keep | G1: Cum.
B2: S6 - Un p'tit déj à Paris | C2: Une amie te fait visiter Paris | G2: =IF(F2="x",COUNTA($F$2:F2),".") -> . | H2: =IF(F2="x",B2,"---") -> ---
B3: Un appartement | F3: x | G3: =IF(F3="x",COUNTA($F$2:F3),".") -> 1 | H3: =IF(F3="x",B3,"---") -> Un appartement
B4: Elle a un appartement à Paris | F4: x | G4: =IF(F4="x",COUNTA($F$2:F4),".") -> 2 | H4: =IF(F4="x",B4,"---") -> Elle a un appartement à Paris
B5: Mon amie a un grand appartement | G5: =IF(F5="x",COUNTA($F$2:F5),".") -> . | H5: =IF(F5="x",B5,"---") -> ---
B6: Elle peut voir Paris | G6: =IF(F6="x",COUNTA($F$2:F6),".") -> . | H6: =IF(F6="x",B6,"---") -> ---
B7: Elle peut voir tout Paris | F7: x | G7: =IF(F7="x",COUNTA($F$2:F7),".") -> 3 | H7: =IF(F7="x",B7,"---") -> Elle peut voir tout Paris
B8: C'est magnifique! | F8: x | G8: =IF(F8="x",COUNTA($F$2:F8),".") -> 4 | H8: =IF(F8="x",B8,"---") -> C'est magnifique!
B9: Et toi, tu as un grand appartement? | F9: x | G9: =IF(F9="x",COUNTA($F$2:F9),".") -> 5 | H9: =IF(F9="x",B9,"---") -> Et toi, tu as un grand appartement?
B10: Non, j'ai un petit appartement | E10: me | F10: x | G10: =IF(F10="x",COUNTA($F$2:F10),".") -> 6 | H10: =IF(F10="x",B10,"---") -> Non, j'ai un petit appartement
B11: Je peux le voir? | C11: guess | E11: te | F11: x | G11: =IF(F11="x",COUNTA($F$2:F11),".") -> 7 | H11: =IF(F11="x",B11,"---") -> Je peux le voir?
B12: Ouah, c'est magnifique! | D12: 2_7 | F12: x | G12: =IF(F12="x",COUNTA($F$2:F12),".") -> 8 | H12: =IF(F12="x",B12,"---") -> Ouah, c'est magnifique!
B13: Je peux te voir | G13: =IF(F13="x",COUNTA($F$2:F13),".") -> . | H13: =IF(F13="x",B13,"---") -> ---
B14: Tu peux me voir? | F14: x | G14: =IF(F14="x",COUNTA($F$2:F14),".") -> 9 | H14: =IF(F14="x",B14,"---") -> Tu peux me voir?
B15: Il peut le voir | F15: x | G15: =IF(F15="x",COUNTA($F$2:F15),".") -> 10 | H15: =IF(F15="x",B15,"---") -> Il peut le voir
B16: Ils peuvent le voir | F16: x | G16: =IF(F16="x",COUNTA($F$2:F16),".") -> 11 | H16: =IF(F16="x",B16,"---") -> Ils peuvent le voir
B17: Ils peuvent me comprendre | G17: =IF(F17="x",COUNTA($F$2:F17),".") -> . | H17: =IF(F17="x",B17,"---") -> ---
B18: On peut | G18: =IF(F18="x",COUNTA($F$2:F18),".") -> . | H18: =IF(F18="x",B18,"---") -> ---
B19: On peut voir Paris | G19: =IF(F19="x",COUNTA($F$2:F19),".") -> . | H19: =IF(F19="x",B19,"---") -> ---
B20: On peut voir tout Paris | F20: x | G20: =IF(F20="x",COUNTA($F$2:F20),".") -> 12 | H20: =IF(F20="x",B20,"---") -> On peut voir tout Paris
B21: Tu peux voir ma voiture? | F21: x | G21: =IF(F21="x",COUNTA($F$2:F21),".") -> 13 | H21: =IF(F21="x",B21,"---") -> Tu peux voir ma voiture?
B22: Non, elle est où? | F22: x | G22: =IF(F22="x",COUNTA($F$2:F22),".") -> 14 | H22: =IF(F22="x",B22,"---") -> Non, elle est où?
B23: Ici, tu peux la voir? | C23: Careful with genre, cf english "I have a sister. Oh can I see it?" | F23: x | G23: =IF(F23="x",COUNTA($F$2:F23),".") -> 15 | H23: =IF(F23="x",B23,"---") -> Ici, tu peux la voir?
B24: Ah oui | G24: =IF(F24="x",COUNTA($F$2:F24),".") -> . | H24: =IF(F24="x",B24,"---") -> ---
B25: Tu peux voir le restau? | F25: x | G25: =IF(F25="x",COUNTA($F$2:F25),".") -> 16 | H25: =IF(F25="x",B25,"---") -> Tu peux voir le restau?
B26: Tu peux le voir? | C26: "le" is often blurred in connected speech -> J'peux l'voir? | G26: =IF(F26="x",COUNTA($F$2:F26),".") -> . | H26: =IF(F26="x",B26,"---") -> ---
B27: Non, il est où? | F27: x | G27: =IF(F27="x",COUNTA($F$2:F27),".") -> 17 | H27: =IF(F27="x",B27,"---") -> Non, il est où?
B28: Où et le restaurant? | G28: =IF(F28="x",COUNTA($F$2:F28),".") -> . | H28: =IF(F28="x",B28,"---") -> ---
B29: Il est là-bas | F29: x | G29: =IF(F29="x",COUNTA($F$2:F29),".") -> 18 | H29: =IF(F29="x",B29,"---") -> Il est là-bas
B30: On peut déjeuner là-bas | F30: x | G30: =IF(F30="x",COUNTA($F$2:F30),".") -> 19 | H30: =IF(F30="x",B30,"---") -> On peut déjeuner là-bas
B31: Maintenant? | F31: x | G31: =IF(F31="x",COUNTA($F$2:F31),".") -> 20 | H31: =IF(F31="x",B31,"---") -> Maintenant?
B32: Non, pas maintenant! | F32: x | G32: =IF(F32="x",COUNTA($F$2:F32),".") -> 21 | H32: =IF(F32="x",B32,"---") -> Non, pas maintenant!
B33: Maintenant, on peut prendre le petit-déjeuner | C33: small lunch | F33: x | G33: =IF(F33="x",COUNTA($F$2:F33),".") -> 22 | H33: =IF(F33="x",B33,"---") -> Maintenant, on peut prendre le petit-déjeuner
B34: C'est délicieux! | F34: x | G34: =IF(F34="x",COUNTA($F$2:F34),".") -> 23 | H34: =IF(F34="x",B34,"---") -> C'est délicieux!

Sheet S7
A1: Type | B1: Fr | C1: Notes | D1: PN track start | E1: New Item | F1: Keep | G1: Cum.
B2: S7 - Un p'tit déj à Paris 2? | C2: Vous avez acheté à manger et tu cuisine pour ton amie | G2: =IF(F2="x",COUNTA($F$2:F2),".") -> . | H2: =IF(F2="x",B2,"---") -> ---
B3: Tu as déjeuné avec ton amie | E3: ton | F3: x | G3: =IF(F3="x",COUNTA($F$2:F3),".") -> 1 | H3: =IF(F3="x",B3,"---") -> Tu as déjeuné avec ton amie
B4: Le retaurant, en France, c'est délicieux, mais c'est très cher! | E4: cher | F4: x | G4: =IF(F4="x",COUNTA($F$2:F4),".") -> 2 | H4: =IF(F4="x",B4,"---") -> Le retaurant, en France, c'est délicieux, mais c'est très cher!
B5: Tu as acheté à manger avec mon amie pour le diner | E5: acheter + à manger | F5: x | G5: =IF(F5="x",COUNTA($F$2:F5),".") -> 3 | H5: =IF(F5="x",B5,"---") -> Tu as acheté à manger avec mon amie pour le diner
B6: Tu as diné avec ton amie | F6: x | G6: =IF(F6="x",COUNTA($F$2:F6),".") -> 4 | H6: =IF(F6="x",B6,"---") -> Tu as diné avec ton amie
B7: Ce soir, vous avez mangé à la maison | E7: avez | F7: x | G7: =IF(F7="x",COUNTA($F$2:F7),".") -> 5 | H7: =IF(F7="x",B7,"---") -> Ce soir, vous avez mangé à la maison
B8: Je peux préparer à manger pour toi | F8: x | G8: =IF(F8="x",COUNTA($F$2:F8),".") -> 6 | H8: =IF(F8="x",B8,"---") -> Je peux préparer à manger pour toi
B9: Super, merci! | F9: x | G9: =IF(F9="x",COUNTA($F$2:F9),".") -> 7 | H9: =IF(F9="x",B9,"---") -> Super, merci!
B10: C'est quoi? | F10: x | G10: =IF(F10="x",COUNTA($F$2:F10),".") -> 8 | H10: =IF(F10="x",B10,"---") -> C'est quoi?
B11: Tu as un chien? | F11: x | G11: =IF(F11="x",COUNTA($F$2:F11),".") -> 9 | H11: =IF(F11="x",B11,"---") -> Tu as un chien?
B12: Oui, j'ai un chien | G12: =IF(F12="x",COUNTA($F$2:F12),".") -> . | H12: =IF(F12="x",B12,"---") -> ---
B13: Où est-il? | F13: x | G13: =IF(F13="x",COUNTA($F$2:F13),".") -> 10 | H13: =IF(F13="x",B13,"---") -> Où est-il?
B14: Je peux le voir | G14: =IF(F14="x",COUNTA($F$2:F14),".") -> . | H14: =IF(F14="x",B14,"---") -> ---
B15: Est-ce que je peux le voir? | F15: x | G15: =IF(F15="x",COUNTA($F$2:F15),".") -> 11 | H15: =IF(F15="x",B15,"---") -> Est-ce que je peux le voir?
B16: Oui bien sûr! | E16: bien sûr | G16: =IF(F16="x",COUNTA($F$2:F16),".") -> . | H16: =IF(F16="x",B16,"---") -> ---
B17: Il est ici | F17: x | G17: =IF(F17="x",COUNTA($F$2:F17),".") -> 12 | H17: =IF(F17="x",B17,"---") -> Il est ici
B18: Il est mignon ! | F18: x | G18: =IF(F18="x",COUNTA($F$2:F18),".") -> 13 | H18: =IF(F18="x",B18,"---") -> Il est mignon !
B19: C'est quoi son nom? | F19: x | G19: =IF(F19="x",COUNTA($F$2:F19),".") -> 14 | H19: =IF(F19="x",B19,"---") -> C'est quoi son nom?
B20: Son nom c'est Biscuit | F20: x | G20: =IF(F20="x",COUNTA($F$2:F20),".") -> 15 | H20: =IF(F20="x",B20,"---") -> Son nom c'est Biscuit
B21: Bonjour Biscuit, moi c'est Nga | F21: x | G21: =IF(F21="x",COUNTA($F$2:F21),".") -> 16 | H21: =IF(F21="x",B21,"---") -> Bonjour Biscuit, moi c'est Nga
B22: N-G-A | F22: x | G22: =IF(F22="x",COUNTA($F$2:F22),".") -> 17 | H22: =IF(F22="x",B22,"---") -> N-G-A
B23: Oh, c'est un nom exotique | F23: x | G23: =IF(F23="x",COUNTA($F$2:F23),".") -> 18 | H23: =IF(F23="x",B23,"---") -> Oh, c'est un nom exotique
B24: Oui, c'est Vietnamien | F24: x | G24: =IF(F24="x",COUNTA($F$2:F24),".") -> 19 | H24: =IF(F24="x",B24,"---") -> Oui, c'est Vietnamien
B25: Ton chien peux manger du chocolat? | E25: du | F25: x | G25: =IF(F25="x",COUNTA($F$2:F25),".") -> 20 | H25: =IF(F25="x",B25,"---") -> Ton chien peux manger du chocolat?

Sheet S8
A1: Type | B1: Fr | C1: Notes | D1: PN | E1: New Item | F1: Keep | G1: Cum.
B2: S8 - Un p'tit déj à Paris 3? | C2: Une amie te fait visiter Paris | G2: =IF(OR(F2="x",F2="x1",F2="x2",F2="x3",F2="x1'"),COUNTA($F$2:F2),".") -> . | H2: =IF(F2="x",B2,IF(AND(F2="x1",F3="x2",F4="x3"),"~ "&B2&CHAR(10)&"~ "&B3&CHAR(10)&"~ "&B4,IF(AND(F2="x1",F3="x2"),"~ "&B2&CHAR(10)&"~ "&B3,IF(AND(F2="x1",F3="x1'"),B2&" "&B3,"---")))) -> ---
A3: last | B3: Ton chien peux manger du chocolat? | G3: =IF(OR(F3="x",F3="x1",F3="x2",F3="x3",F3="x1'"),COUNTA($F$2:F3),".") -> . | H3: =IF(F3="x",B3,IF(AND(F3="x1",F4="x2",F5="x3"),"~ "&B3&CHAR(10)&"~ "&B4&CHAR(10)&"~ "&B5,IF(AND(F3="x1",F4="x2"),"~ "&B3&CHAR(10)&"~ "&B4,IF(AND(F3="x1",F4="x1'"),B3&" "&B4,"---")))) -> ---
B4: Non, il peut pas | G4: =IF(OR(F4="x",F4="x1",F4="x2",F4="x3",F4="x1'"),COUNTA($F$2:F4),".") -> . | H4: =IF(F4="x",B4,IF(AND(F4="x1",F5="x2",F6="x3"),"~ "&B4&CHAR(10)&"~ "&B5&CHAR(10)&"~ "&B6,IF(AND(F4="x1",F5="x2"),"~ "&B4&CHAR(10)&"~ "&B5,IF(AND(F4="x1",F5="x1'"),B4&" "&B5,"---")))) -> ---
B5: C'est dangereux | E5: dangereux | F5: x | G5: =IF(OR(F5="x",F5="x1",F5="x2",F5="x3",F5="x1'"),COUNTA($F$2:F5),".") -> 1 | H5: =IF(F5="x",B5,IF(AND(F5="x1",F6="x2",F7="x3"),"~ "&B5&CHAR(10)&"~ "&B6&CHAR(10)&"~ "&B7,IF(AND(F5="x1",F6="x2"),"~ "&B5&CHAR(10)&"~ "&B6,IF(AND(F5="x1",F6="x1'"),B5&" "&B6,"---")))) -> C'est dangereux
B6: Mais il peut manger des croissants. | C6: ask favorite french dessert | G6: =IF(OR(F6="x",F6="x1",F6="x2",F6="x3",F6="x1'"),COUNTA($F$2:F6),".") -> . | H6: =IF(F6="x",B6,IF(AND(F6="x1",F7="x2",F8="x3"),"~ "&B6&CHAR(10)&"~ "&B7&CHAR(10)&"~ "&B8,IF(AND(F6="x1",F7="x2"),"~ "&B6&CHAR(10)&"~ "&B7,IF(AND(F6="x1",F7="x1'"),B6&" "&B7,"---")))) -> ---
B7: Ah, on peut acheter des croissants pour Biscuit | F7: x | G7: =IF(OR(F7="x",F7="x1",F7="x2",F7="x3",F7="x1'"),COUNTA($F$2:F7),".") -> 2 | H7: =IF(F7="x",B7,IF(AND(F7="x1",F8="x2",F9="x3"),"~ "&B7&CHAR(10)&"~ "&B8&CHAR(10)&"~ "&B9,IF(AND(F7="x1",F8="x2"),"~ "&B7&CHAR(10)&"~ "&B8,IF(AND(F7="x1",F8="x1'"),B7&" "&B8,"---")))) -> Ah, on peut acheter des croissants pour Biscuit
B8: On peut en acheter maintenant? | D8: 349-360 | E8: en | F8: x | G8: =IF(OR(F8="x",F8="x1",F8="x2",F8="x3",F8="x1'"),COUNTA($F$2:F8),".") -> 3 | H8: =IF(F8="x",B8,IF(AND(F8="x1",F9="x2",F10="x3"),"~ "&B8&CHAR(10)&"~ "&B9&CHAR(10)&"~ "&B10,IF(AND(F8="x1",F9="x2"),"~ "&B8&CHAR(10)&"~ "&B9,IF(AND(F8="x1",F9="x1'"),B8&" "&B9,"---")))) -> On peut en acheter maintenant?
A9: Drill en | B9: Je peux le manger? | G9: =IF(OR(F9="x",F9="x1",F9="x2",F9="x3",F9="x1'"),COUNTA($F$2:F9),".") -> . | H9: =IF(F9="x",B9,IF(AND(F9="x1",F10="x2",F11="x3"),"~ "&B9&CHAR(10)&"~ "&B10&CHAR(10)&"~ "&B11,IF(AND(F9="x1",F10="x2"),"~ "&B9&CHAR(10)&"~ "&B10,IF(AND(F9="x1",F10="x1'"),B9&" "&B10,"---")))) -> ---
B10: Je peux en manger? | F10: x1 | G10: =IF(OR(F10="x",F10="x1",F10="x2",F10="x3",F10="x1'"),COUNTA($F$2:F10),".") -> 4 | H10: =IF(F10="x",B10,IF(AND(F10="x1",F11="x2",F12="x3"),"~ "&B10&CHAR(10)&"~ "&B11&CHAR(10)&"~ "&B12,IF(AND(F10="x1",F11="x2"),"~ "&B10&CHAR(10)&"~ "&B11,IF(AND(F10="x1",F11="x1'"),B10&" "&B11,"---")))) -> ~ Je peux en manger? ~ Oui, tu peux en manger, pas de probleme.
B11: Oui, tu peux en manger, pas de probleme. | C11: not like "stay" | F11: x2 | G11: =IF(OR(F11="x",F11="x1",F11="x2",F11="x3",F11="x1'"),COUNTA($F$2:F11),".") -> 5 | H11: =IF(F11="x",B11,IF(AND(F11="x1",F12="x2",F13="x3"),"~ "&B11&CHAR(10)&"~ "&B12&CHAR(10)&"~ "&B13,IF(AND(F11="x1",F12="x2"),"~ "&B11&CHAR(10)&"~ "&B12,IF(AND(F11="x1",F12="x1'"),B11&" "&B12,"---")))) -> ---
B12: Je veux en prendre. | E12: veux | G12: =IF(OR(F12="x",F12="x1",F12="x2",F12="x3",F12="x1'"),COUNTA($F$2:F12),".") -> . | H12: =IF(F12="x",B12,IF(AND(F12="x1",F13="x2",F14="x3"),"~ "&B12&CHAR(10)&"~ "&B13&CHAR(10)&"~ "&B14,IF(AND(F12="x1",F13="x2"),"~ "&B12&CHAR(10)&"~ "&B13,IF(AND(F12="x1",F13="x1'"),B12&" "&B13,"---")))) -> ---
B13: Il y a des chocolats a la maison. | E13: il y a | F13: x1 | G13: =IF(OR(F13="x",F13="x1",F13="x2",F13="x3",F13="x1'"),COUNTA($F$2:F13),".") -> 6 | H13: =IF(F13="x",B13,IF(AND(F13="x1",F14="x2",F15="x3"),"~ "&B13&CHAR(10)&"~ "&B14&CHAR(10)&"~ "&B15,IF(AND(F13="x1",F14="x2"),"~ "&B13&CHAR(10)&"~ "&B14,IF(AND(F13="x1",F14="x1'"),B13&" "&B14,"---")))) -> ~ Il y a des chocolats a la maison. ~ Je veux en prendre.
B14: Je veux en prendre. | F14: x2 | G14: =IF(OR(F14="x",F14="x1",F14="x2",F14="x3",F14="x1'"),COUNTA($F$2:F14),".") -> 7 | H14: =IF(F14="x",B14,IF(AND(F14="x1",F15="x2",F16="x3"),"~ "&B14&CHAR(10)&"~ "&B15&CHAR(10)&"~ "&B16,IF(AND(F14="x1",F15="x2"),"~ "&B14&CHAR(10)&"~ "&B15,IF(AND(F14="x1",F15="x1'"),B14&" "&B15,"---")))) -> ---
B15: Il y a du café? | F15: x1 | G15: =IF(OR(F15="x",F15="x1",F15="x2",F15="x3",F15="x1'"),COUNTA($F$2:F15),".") -> 8 | H15: =IF(F15="x",B15,IF(AND(F15="x1",F16="x2",F17="x3"),"~ "&B15&CHAR(10)&"~ "&B16&CHAR(10)&"~ "&B17,IF(AND(F15="x1",F16="x2"),"~ "&B15&CHAR(10)&"~ "&B16,IF(AND(F15="x1",F16="x1'"),B15&" "&B16,"---")))) -> ~ Il y a du café? ~ Non, je veux en préprarer.
B16: Non, je veux en préprarer. | F16: x2 | G16: =IF(OR(F16="x",F16="x1",F16="x2",F16="x3",F16="x1'"),COUNTA($F$2:F16),".") -> 9 | H16: =IF(F16="x",B16,IF(AND(F16="x1",F17="x2",F18="x3"),"~ "&B16&CHAR(10)&"~ "&B17&CHAR(10)&"~ "&B18,IF(AND(F16="x1",F17="x2"),"~ "&B16&CHAR(10)&"~ "&B17,IF(AND(F16="x1",F17="x1'"),B16&" "&B17,"---")))) -> ---
A17: cont. | B17: Non, pas maintenant. | G17: =IF(OR(F17="x",F17="x1",F17="x2",F17="x3",F17="x1'"),COUNTA($F$2:F17),".") -> . | H17: =IF(F17="x",B17,IF(AND(F17="x1",F18="x2",F19="x3"),"~ "&B17&CHAR(10)&"~ "&B18&CHAR(10)&"~ "&B19,IF(AND(F17="x1",F18="x2"),"~ "&B17&CHAR(10)&"~ "&B18,IF(AND(F17="x1",F18="x1'"),B17&" "&B18,"---")))) -> ---
B18: Je veux manger d'abord. | E18: d'abord | F18: x | G18: =IF(OR(F18="x",F18="x1",F18="x2",F18="x3",F18="x1'"),COUNTA($F$2:F18),".") -> 10 | H18: =IF(F18="x",B18,IF(AND(F18="x1",F19="x2",F20="x3"),"~ "&B18&CHAR(10)&"~ "&B19&CHAR(10)&"~ "&B20,IF(AND(F18="x1",F19="x2"),"~ "&B18&CHAR(10)&"~ "&B19,IF(AND(F18="x1",F19="x1'"),B18&" "&B19,"---")))) -> Je veux manger d'abord.
B19: Ah, tu as tres faim, c'est ca? | F19: x1 | G19: =IF(OR(F19="x",F19="x1",F19="x2",F19="x3",F19="x1'"),COUNTA($F$2:F19),".") -> 11 | H19: =IF(F19="x",B19,IF(AND(F19="x1",F20="x2",F21="x3"),"~ "&B19&CHAR(10)&"~ "&B20&CHAR(10)&"~ "&B21,IF(AND(F19="x1",F20="x2"),"~ "&B19&CHAR(10)&"~ "&B20,IF(AND(F19="x1",F20="x1'"),B19&" "&B20,"---")))) -> ~ Ah, tu as tres faim, c'est ca? ~ Exactement!
B20: Exactement! | F20: x2 | G20: =IF(OR(F20="x",F20="x1",F20="x2",F20="x3",F20="x1'"),COUNTA($F$2:F20),".") -> 12 | H20: =IF(F20="x",B20,IF(AND(F20="x1",F21="x2",F22="x3"),"~ "&B20&CHAR(10)&"~ "&B21&CHAR(10)&"~ "&B22,IF(AND(F20="x1",F21="x2"),"~ "&B20&CHAR(10)&"~ "&B21,IF(AND(F20="x1",F21="x1'"),B20&" "&B21,"---")))) -> ---
B21: Comment est le diné? | E21: comment | F21: x1 | G21: =IF(OR(F21="x",F21="x1",F21="x2",F21="x3",F21="x1'"),COUNTA($F$2:F21),".") -> 13 | H21: =IF(F21="x",B21,IF(AND(F21="x1",F22="x2",F23="x3"),"~ "&B21&CHAR(10)&"~ "&B22&CHAR(10)&"~ "&B23,IF(AND(F21="x1",F22="x2"),"~ "&B21&CHAR(10)&"~ "&B22,IF(AND(F21="x1",F22="x1'"),B21&" "&B22,"---")))) -> Comment est le diné? C'est bon?
B22: C'est bon? | E22: bon | F22: x1' | G22: =IF(OR(F22="x",F22="x1",F22="x2",F22="x3",F22="x1'"),COUNTA($F$2:F22),".") -> 14 | H22: =IF(F22="x",B22,IF(AND(F22="x1",F23="x2",F24="x3"),"~ "&B22&CHAR(10)&"~ "&B23&CHAR(10)&"~ "&B24,IF(AND(F22="x1",F23="x2"),"~ "&B22&CHAR(10)&"~ "&B23,IF(AND(F22="x1",F23="x1'"),B22&" "&B23,"---")))) -> ---
B23: Le diné est parfait, merci! | E23: parfait | F23: x | G23: =IF(OR(F23="x",F23="x1",F23="x2",F23="x3",F23="x1'"),COUNTA($F$2:F23),".") -> 15 | H23: =IF(F23="x",B23,IF(AND(F23="x1",F24="x2",F25="x3"),"~ "&B23&CHAR(10)&"~ "&B24&CHAR(10)&"~ "&B25,IF(AND(F23="x1",F24="x2"),"~ "&B23&CHAR(10)&"~ "&B24,IF(AND(F23="x1",F24="x1'"),B23&" "&B24,"---")))) -> Le diné est parfait, merci!
B24: C''est parfait Nga! | G24: =IF(OR(F24="x",F24="x1",F24="x2",F24="x3",F24="x1'"),COUNTA($F$2:F24),".") -> . | H24: =IF(F24="x",B24,IF(AND(F24="x1",F25="x2",F26="x3"),"~ "&B24&CHAR(10)&"~ "&B25&CHAR(10)&"~ "&B26,IF(AND(F24="x1",F25="x2"),"~ "&B24&CHAR(10)&"~ "&B25,IF(AND(F24="x1",F25="x1'"),B24&" "&B25,"---")))) -> ---
B25: Tu veux prendre un verre? | E25: verre | F25: x1 | G25: =IF(OR(F25="x",F25="x1",F25="x2",F25="x3",F25="x1'"),COUNTA($F$2:F25),".") -> 16 | H25: =IF(F25="x",B25,IF(AND(F25="x1",F26="x2",F27="x3"),"~ "&B25&CHAR(10)&"~ "&B26&CHAR(10)&"~ "&B27,IF(AND(F25="x1",F26="x2"),"~ "&B25&CHAR(10)&"~ "&B26,IF(AND(F25="x1",F26="x1'"),B25&" "&B26,"---")))) -> ~ Tu veux prendre un verre? ~ Pourquoi pas! On peut discuter.
B26: Pourquoi pas! On peut discuter. | F26: x2 | G26: =IF(OR(F26="x",F26="x1",F26="x2",F26="x3",F26="x1'"),COUNTA($F$2:F26),".") -> 17 | H26: =IF(F26="x",B26,IF(AND(F26="x1",F27="x2",F28="x3"),"~ "&B26&CHAR(10)&"~ "&B27&CHAR(10)&"~ "&B28,IF(AND(F26="x1",F27="x2"),"~ "&B26&CHAR(10)&"~ "&B27,IF(AND(F26="x1",F27="x1'"),B26&" "&B27,"---")))) -> ---
B27: Je peux rester chez toi ce soir? | E27: rester | F27: x1 | G27: =IF(OR(F27="x",F27="x1",F27="x2",F27="x3",F27="x1'"),COUNTA($F$2:F27),".") -> 18 | H27: =IF(F27="x",B27,IF(AND(F27="x1",F28="x2",F29="x3"),"~ "&B27&CHAR(10)&"~ "&B28&CHAR(10)&"~ "&B29,IF(AND(F27="x1",F28="x2"),"~ "&B27&CHAR(10)&"~ "&B28,IF(AND(F27="x1",F28="x1'"),B27&" "&B28,"---")))) -> Je peux rester chez toi ce soir? C'est possible?
B28: C'est possible? | D28: 2_10 | E28: dormir | F28: x1' | G28: =IF(OR(F28="x",F28="x1",F28="x2",F28="x3",F28="x1'"),COUNTA($F$2:F28),".") -> 19 | H28: =IF(F28="x",B28,IF(AND(F28="x1",F29="x2",F30="x3"),"~ "&B28&CHAR(10)&"~ "&B29&CHAR(10)&"~ "&B30,IF(AND(F28="x1",F29="x2"),"~ "&B28&CHAR(10)&"~ "&B29,IF(AND(F28="x1",F29="x1'"),B28&" "&B29,"---")))) -> ---
B29: Est-ce que je peux dormir ici ce soir? | G29: =IF(OR(F29="x",F29="x1",F29="x2",F29="x3",F29="x1'"),COUNTA($F$2:F29),".") -> . | H29: =IF(F29="x",B29,IF(AND(F29="x1",F30="x2",F31="x3"),"~ "&B29&CHAR(10)&"~ "&B30&CHAR(10)&"~ "&B31,IF(AND(F29="x1",F30="x2"),"~ "&B29&CHAR(10)&"~ "&B30,IF(AND(F29="x1",F30="x1'"),B29&" "&B30,"---")))) -> ---
B30: Est-ce que je peux dormir chez toi ce soir? | E30: possible | F30: x1 | G30: =IF(OR(F30="x",F30="x1",F30="x2",F30="x3",F30="x1'"),COUNTA($F$2:F30),".") -> 20 | H30: =IF(F30="x",B30,IF(AND(F30="x1",F31="x2",F32="x3"),"~ "&B30&CHAR(10)&"~ "&B31&CHAR(10)&"~ "&B32,IF(AND(F30="x1",F31="x2"),"~ "&B30&CHAR(10)&"~ "&B31,IF(AND(F30="x1",F31="x1'"),B30&" "&B31,"---")))) -> ~ Est-ce que je peux dormir chez toi ce soir? ~ D'accord.
B31: D'accord. | E31: d'accord | F31: x2 | G31: =IF(OR(F31="x",F31="x1",F31="x2",F31="x3",F31="x1'"),COUNTA($F$2:F31),".") -> 21 | H31: =IF(F31="x",B31,IF(AND(F31="x1",F32="x2",F33="x3"),"~ "&B31&CHAR(10)&"~ "&B32&CHAR(10)&"~ "&B33,IF(AND(F31="x1",F32="x2"),"~ "&B31&CHAR(10)&"~ "&B32,IF(AND(F31="x1",F32="x1'"),B31&" "&B32,"---")))) -> ---
B32: Non, désolé, c'est pas possible. | E32: d2sol2 | G32: =IF(OR(F32="x",F32="x1",F32="x2",F32="x3",F32="x1'"),COUNTA($F$2:F32),".") -> . | H32: =IF(F32="x",B32,IF(AND(F32="x1",F33="x2",F34="x3"),"~ "&B32&CHAR(10)&"~ "&B33&CHAR(10)&"~ "&B34,IF(AND(F32="x1",F33="x2"),"~ "&B32&CHAR(10)&"~ "&B33,IF(AND(F32="x1",F33="x1'"),B32&" "&B33,"---")))) -> ---
B33: Merci beaucoup! | E33: beaucoup | G33: =IF(OR(F33="x",F33="x1",F33="x2",F33="x3",F33="x1'"),COUNTA($F$2:F33),".") -> . | H33: =IF(F33="x",B33,IF(AND(F33="x1",F34="x2",F35="x3"),"~ "&B33&CHAR(10)&"~ "&B34&CHAR(10)&"~ "&B35,IF(AND(F33="x1",F34="x2"),"~ "&B33&CHAR(10)&"~ "&B34,IF(AND(F33="x1",F34="x1'"),B33&" "&B34,"---")))) -> ---
B34: Où est ma chambre? | F34: x1 | G34: =IF(OR(F34="x",F34="x1",F34="x2",F34="x3",F34="x1'"),COUNTA($F$2:F34),".") -> 22 | H34: =IF(F34="x",B34,IF(AND(F34="x1",F35="x2",F36="x3"),"~ "&B34&CHAR(10)&"~ "&B35&CHAR(10)&"~ "&B36,IF(AND(F34="x1",F35="x2"),"~ "&B34&CHAR(10)&"~ "&B35,IF(AND(F34="x1",F35="x1'"),B34&" "&B35,"---")))) -> ~ Où est ma chambre? ~ Elle est là-bas.
B35: Elle est là-bas. | F35: x2 | G35: =IF(OR(F35="x",F35="x1",F35="x2",F35="x3",F35="x1'"),COUNTA($F$2:F35),".") -> 23 | H35: =IF(F35="x",B35,IF(AND(F35="x1",F36="x2",F37="x3"),"~ "&B35&CHAR(10)&"~ "&B36&CHAR(10)&"~ "&B37,IF(AND(F35="x1",F36="x2"),"~ "&B35&CHAR(10)&"~ "&B36,IF(AND(F35="x1",F36="x1'"),B35&" "&B36,"---")))) -> ---
B36: Je suis fatiguée. | F36: x1 | G36: =IF(OR(F36="x",F36="x1",F36="x2",F36="x3",F36="x1'"),COUNTA($F$2:F36),".") -> 24 | H36: =IF(F36="x",B36,IF(AND(F36="x1",F37="x2",F38="x3"),"~ "&B36&CHAR(10)&"~ "&B37&CHAR(10)&"~ "&B38,IF(AND(F36="x1",F37="x2"),"~ "&B36&CHAR(10)&"~ "&B37,IF(AND(F36="x1",F37="x1'"),B36&" "&B37,"---")))) -> Je suis fatiguée. Je veux dormir maintenant.
B37: Je veux dormir maintenant. | F37: x1' | G37: =IF(OR(F37="x",F37="x1",F37="x2",F37="x3",F37="x1'"),COUNTA($F$2:F37),".") -> 25 | H37: =IF(F37="x",B37,IF(AND(F37="x1",F38="x2",F39="x3"),"~ "&B37&CHAR(10)&"~ "&B38&CHAR(10)&"~ "&B39,IF(AND(F37="x1",F38="x2"),"~ "&B37&CHAR(10)&"~ "&B38,IF(AND(F37="x1",F38="x1'"),B37&" "&B38,"---")))) -> ---
B38: Est-ce que tu veux prendre ta douche d'abord? | F38: x | G38: =IF(OR(F38="x",F38="x1",F38="x2",F38="x3",F38="x1'"),COUNTA($F$2:F38),".") -> 26 | H38: =IF(F38="x",B38,IF(AND(F38="x1",F39="x2",F40="x3"),"~ "&B38&CHAR(10)&"~ "&B39&CHAR(10)&"~ "&B40,IF(AND(F38="x1",F39="x2"),"~ "&B38&CHAR(10)&"~ "&B39,IF(AND(F38="x1",F39="x1'"),B38&" "&B39,"---")))) -> Est-ce que tu veux prendre ta douche d'abord?
H41: C'est dangereux
H42: Ah, on peut acheter des croissants pour Biscuit
...

Sheet S9
A1: PN | B1: Type | C1: New Item | D1: Fr | E1: Notes | F1: Keep | G1: Cum. | H1: Cards
B2: lesson title | D2: S8 - Un p'tit déj à Paris 3? | E2: Une amie te fait visiter Paris | G2: =IF(F2="x",COUNTA($F$2:F2),".") -> . | H2: =IF(F2="x",D2,IF(AND(F2="x1",F3="x2",F4="x3"),"~"&D2&CHAR(10)&"~ "&D3&CHAR(10)&"~ "&D4,IF(AND(F2="x1",F3="x2"),"~"&D2&CHAR(10)&"~ "&D3,IF(AND(F2="x1",F3="x1'"),D2&" "&D3,"---")))) -> ---
B3: last | D3: Est-ce que tu veux prendre ta douche d'abord? | G3: =IF(F3="x",COUNTA($F$2:F3),".") -> . | H3: =IF(F3="x",D3,IF(AND(F3="x1",F4="x2",F5="x3"),"~"&D3&CHAR(10)&"~ "&D4&CHAR(10)&"~ "&D5,IF(AND(F3="x1",F4="x2"),"~"&D3&CHAR(10)&"~ "&D4,IF(AND(F3="x1",F4="x1'"),D3&" "&D4,"---")))) -> ---
C4: Attendre | D4: Euh, non je vais attendre demain. | F4: x | G4: =IF(F4="x",COUNTA($F$2:F4),".") -> 1 | H4: =IF(F4="x",D4,IF(AND(F4="x1",F5="x2",F6="x3"),"~ "&D4&CHAR(10)&"~ "&D5&CHAR(10)&"~ "&D6,IF(AND(F4="x1",F5="x2"),"~ "&D4&CHAR(10)&"~ "&D5,IF(AND(F4="x1",F5="x1'"),D4&" "&D5,"---")))) -> Euh, non je vais attendre demain.
C5: Sont + toilettes | D5: Où sont les toilettes? | F5: x1 | G5: =IF(F5="x",COUNTA($F$2:F5),".") -> . | H5: =IF(F5="x",D5,IF(AND(F5="x1",F6="x2",F7="x3"),"~ "&D5&CHAR(10)&"~ "&D6&CHAR(10)&"~ "&D7,IF(AND(F5="x1",F6="x2"),"~ "&D5&CHAR(10)&"~ "&D6,IF(AND(F5="x1",F6="x1'"),D5&" "&D6,"---")))) -> ~ Où sont les toilettes? ~ Les toilettes sont là-bas, à droite.
C6: Droite | D6: Les toilettes sont là-bas, à droite. | F6: x2 | G6: =IF(F6="x",COUNTA($F$2:F6),".") -> . | H6: =IF(F6="x",D6,IF(AND(F6="x1",F7="x2",F8="x3"),"~ "&D6&CHAR(10)&"~ "&D7&CHAR(10)&"~ "&D8,IF(AND(F6="x1",F7="x2"),"~ "&D6&CHAR(10)&"~ "&D7,IF(AND(F6="x1",F7="x1'"),D6&" "&D7,"---")))) -> ---
D7: Bonne nuit | F7: x1 | G7: =IF(F7="x",COUNTA($F$2:F7),".") -> . | H7: =IF(F7="x",D7,IF(AND(F7="x1",F8="x2",F9="x3"),"~ "&D7&CHAR(10)&"~ "&D8&CHAR(10)&"~ "&D9,IF(AND(F7="x1",F8="x2"),"~ "&D7&CHAR(10)&"~ "&D8,IF(AND(F7="x1",F8="x1'"),D7&" "&D8,"---")))) -> ~ Bonne nuit ~ Toi aussi
C8: Aussi | D8: Toi aussi | F8: x2 | G8: =IF(F8="x",COUNTA($F$2:F8),".") -> . | H8: =IF(F8="x",D8,IF(AND(F8="x1",F9="x2",F10="x3"),"~ "&D8&CHAR(10)&"~ "&D9&CHAR(10)&"~ "&D10,IF(AND(F8="x1",F9="x2"),"~ "&D8&CHAR(10)&"~ "&D9,IF(AND(F8="x1",F9="x1'"),D8&" "&D9,"---")))) -> ---
C9: Bien + Dormi | D9: Tu as bien dormi? | F9: x1 | G9: =IF(F9="x",COUNTA($F$2:F9),".") -> . | H9: =IF(F9="x",D9,IF(AND(F9="x1",F10="x2",F11="x3"),"~ "&D9&CHAR(10)&"~ "&D10&CHAR(10)&"~ "&D11,IF(AND(F9="x1",F10="x2"),"~ "&D9&CHAR(10)&"~ "&D10,IF(AND(F9="x1",F10="x1'"),D9&" "&D10,"---")))) -> ~ Tu as bien dormi? ~ Oui, et toi? ~ Moi aussi
D10: Oui, et toi? | F10: x2 | G10: =IF(F10="x",COUNTA($F$2:F10),".") -> . | H10: =IF(F10="x",D10,IF(AND(F10="x1",F11="x2",F12="x3"),"~ "&D10&CHAR(10)&"~ "&D11&CHAR(10)&"~ "&D12,IF(AND(F10="x1",F11="x2"),"~ "&D10&CHAR(10)&"~ "&D11,IF(AND(F10="x1",F11="x1'"),D10&" "&D11,"---")))) -> ---
D11: Moi aussi | F11: x3 | G11: =IF(F11="x",COUNTA($F$2:F11),".") -> . | H11: =IF(F11="x",D11,IF(AND(F11="x1",F12="x2",F13="x3"),"~ "&D11&CHAR(10)&"~ "&D12&CHAR(10)&"~ "&D13,IF(AND(F11="x1",F12="x2"),"~ "&D11&CHAR(10)&"~ "&D12,IF(AND(F11="x1",F12="x1'"),D11&" "&D12,"---")))) -> ---
D12: Tu veux prendre ton petit-dej maintenant? | F12: x | G12: =IF(F12="x",COUNTA($F$2:F12),".") -> 9 | H12: =IF(F12="x",D12,IF(AND(F12="x1",F13="x2",F14="x3"),"~ "&D12&CHAR(10)&"~ "&D13&CHAR(10)&"~ "&D14,IF(AND(F12="x1",F13="x2"),"~ "&D12&CHAR(10)&"~ "&D13,IF(AND(F12="x1",F13="x1'"),D12&" "&D13,"---")))) -> Tu veux prendre ton petit-dej maintenant?
C13: Dois | D13: Oui, mais je dois prendre ma douche d'abord | F13: x | G13: =IF(F13="x",COUNTA($F$2:F13),".") -> 10 | H13: =IF(F13="x",D13,IF(AND(F13="x1",F14="x2",F15="x3"),"~ "&D13&CHAR(10)&"~ "&D14&CHAR(10)&"~ "&D15,IF(AND(F13="x1",F14="x2"),"~ "&D13&CHAR(10)&"~ "&D14,IF(AND(F13="x1",F14="x1'"),D13&" "&D14,"---")))) -> Oui, mais je dois prendre ma douche d'abord
B14: P | D14: Je dois prendre mon petit-dej | G14: =IF(F14="x",COUNTA($F$2:F14),".") -> . | H14: =IF(F14="x",D14,IF(AND(F14="x1",F15="x2",F16="x3"),"~ "&D14&CHAR(10)&"~ "&D15&CHAR(10)&"~ "&D16,IF(AND(F14="x1",F15="x2"),"~ "&D14&CHAR(10)&"~ "&D15,IF(AND(F14="x1",F15="x1'"),D14&" "&D15,"---")))) -> ---
D15: Tu dois acheter a manger | G15: =IF(F15="x",COUNTA($F$2:F15),".") -> . | H15: =IF(F15="x",D15,IF(AND(F15="x1",F16="x2",F17="x3"),"~ "&D15&CHAR(10)&"~ "&D16&CHAR(10)&"~ "&D17,IF(AND(F15="x1",F16="x2"),"~ "&D15&CHAR(10)&"~ "&D16,IF(AND(F15="x1",F16="x1'"),D15&" "&D16,"---")))) -> ---
C16: La vie | D16: On doit discuter de la vie | F16: x | G16: =IF(F16="x",COUNTA($F$2:F16),".") -> 11 | H16: =IF(F16="x",D16,IF(AND(F16="x1",F17="x2",F18="x3"),"~ "&D16&CHAR(10)&"~ "&D17&CHAR(10)&"~ "&D18,IF(AND(F16="x1",F17="x2"),"~ "&D16&CHAR(10)&"~ "&D17,IF(AND(F16="x1",F17="x1'"),D16&" "&D17,"---")))) -> On doit discuter de la vie
D17: Tu dois preparer du café | F17: x | G17: =IF(F17="x",COUNTA($F$2:F17),".") -> 12 | H17: =IF(F17="x",D17,IF(AND(F17="x1",F18="x2",F19="x3"),"~ "&D17&CHAR(10)&"~ "&D18&CHAR(10)&"~ "&D19,IF(AND(F17="x1",F18="x2"),"~ "&D17&CHAR(10)&"~ "&D18,IF(AND(F17="x1",F18="x1'"),D17&" "&D18,"---")))) -> Tu dois preparer du café
C18: Partir | D18: Je dois partir maintenant | F18: x1 | G18: =IF(F18="x",COUNTA($F$2:F18),".") -> . | H18: =IF(F18="x",D18,IF(AND(F18="x1",F19="x2",F20="x3"),"~ "&D18&CHAR(10)&"~ "&D19&CHAR(10)&"~ "&D20,IF(AND(F18="x1",F19="x2"),"~ "&D18&CHAR(10)&"~ "&D19,IF(AND(F18="x1",F19="x1'"),D18&" "&D19,"---")))) -> ~ Je dois partir maintenant ~ Non, tu dois manger d'abord!
D19: Non, tu dois manger d'abord! | F19: x2 | G19: =IF(F19="x",COUNTA($F$2:F19),".") -> . | H19: =IF(F19="x",D19,IF(AND(F19="x1",F20="x2",F21="x3"),"~ "&D19&CHAR(10)&"~ "&D20&CHAR(10)&"~ "&D21,IF(AND(F19="x1",F20="x2"),"~ "&D19&CHAR(10)&"~ "&D20,IF(AND(F19="x1",F20="x1'"),D19&" "&D20,"---")))) -> ---
C20: Avant de | D20: Tu dois manger avant de partir | F20: x | G20: =IF(F20="x",COUNTA($F$2:F20),".") -> 15 | H20: =IF(F20="x",D20,IF(AND(F20="x1",F21="x2",F22="x3"),"~ "&D20&CHAR(10)&"~ "&D21&CHAR(10)&"~ "&D22,IF(AND(F20="x1",F21="x2"),"~ "&D20&CHAR(10)&"~ "&D21,IF(AND(F20="x1",F21="x1'"),D20&" "&D21,"---")))) -> Tu dois manger avant de partir
D21: Je dois prendre une douche avant de dormir | F21: x | G21: =IF(F21="x",COUNTA($F$2:F21),".") -> 16 | H21: =IF(F21="x",D21,IF(AND(F21="x1",F22="x2",F23="x3"),"~ "&D21&CHAR(10)&"~ "&D22&CHAR(10)&"~ "&D23,IF(AND(F21="x1",F22="x2"),"~ "&D21&CHAR(10)&"~ "&D22,IF(AND(F21="x1",F22="x1'"),D21&" "&D22,"---")))) -> Je dois prendre une douche avant de dormir
C22: Bon | D22: Bon, d'accord | G22: =IF(F22="x",COUNTA($F$2:F22),".") -> . | H22: =IF(F22="x",D22,IF(AND(F22="x1",F23="x2",F24="x3"),"~ "&D22&CHAR(10)&"~ "&D23&CHAR(10)&"~ "&D24,IF(AND(F22="x1",F23="x2"),"~ "&D22&CHAR(10)&"~ "&D23,IF(AND(F22="x1",F23="x1'"),D22&" "&D23,"---")))) -> ---
C23: Boire + lait | D23: Tu veux boire du lait? | F23: x1 | G23: =IF(F23="x",COUNTA($F$2:F23),".") -> . | H23: =IF(F23="x",D23,IF(AND(F23="x1",F24="x2",F25="x3"),"~ "&D23&CHAR(10)&"~ "&D24&CHAR(10)&"~ "&D25,IF(AND(F23="x1",F24="x2"),"~ "&D23&CHAR(10)&"~ "&D24,IF(AND(F23="x1",F24="x1'"),D23&" "&D24,"---")))) -> ~ Tu veux boire du lait? ~ Non merci, j'en veux pas
C24: en + neg | D24: Non merci, j'en veux pas | F24: x2 | G24: =IF(F24="x",COUNTA($F$2:F24),".") -> . | H24: =IF(F24="x",D24,IF(AND(F24="x1",F25="x2",F26="x3"),"~ "&D24&CHAR(10)&"~ "&D25&CHAR(10)&"~ "&D26,IF(AND(F24="x1",F25="x2"),"~ "&D24&CHAR(10)&"~ "&D25,IF(AND(F24="x1",F25="x1'"),D24&" "&D25,"---")))) -> ---
B25: P | C25: pain | D25: Tu as du pain? | G25: =IF(F25="x",COUNTA($F$2:F25),".") -> . | H25: =IF(F25="x",D25,IF(AND(F25="x1",F26="x2",F27="x3"),"~ "&D25&CHAR(10)&"~ "&D26&CHAR(10)&"~ "&D27,IF(AND(F25="x1",F26="x2"),"~ "&D25&CHAR(10)&"~ "&D26,IF(AND(F25="x1",F26="x1'"),D25&" "&D26,"---")))) -> ---
B26: P | C26: stp | D26: Tu as du pain, stp? | F26: x1 | G26: =IF(F26="x",COUNTA($F$2:F26),".") -> . | H26: =IF(F26="x",D26,IF(AND(F26="x1",F27="x2",F28="x3"),"~ "&D26&CHAR(10)&"~ "&D27&CHAR(10)&"~ "&D28,IF(AND(F26="x1",F27="x2"),"~ "&D26&CHAR(10)&"~ "&D27,IF(AND(F26="x1",F27="x1'"),D26&" "&D27,"---")))) -> ~ Tu as du pain, stp? ~ Non, j'en ai pas achete
B27: P | D27: Non, j'en ai pas achete | F27: x2 | G27: =IF(F27="x",COUNTA($F$2:F27),".") -> . | H27: =IF(F27="x",D27,IF(AND(F27="x1",F28="x2",F29="x3"),"~ "&D27&CHAR(10)&"~ "&D28&CHAR(10)&"~ "&D29,IF(AND(F27="x1",F28="x2"),"~ "&D27&CHAR(10)&"~ "&D28,IF(AND(F27="x1",F28="x1'"),D27&" "&D28,"---")))) -> ---
B28: P | D28: Ah, et tu as du café? | F28: x1 | G28: =IF(F28="x",COUNTA($F$2:F28),".") -> . | H28: =IF(F28="x",D28,IF(AND(F28="x1",F29="x2",F30="x3"),"~ "&D28&CHAR(10)&"~ "&D29&CHAR(10)&"~ "&D30,IF(AND(F28="x1",F29="x2"),"~ "&D28&CHAR(10)&"~ "&D29,IF(AND(F28="x1",F29="x1'"),D28&" "&D29,"---")))) -> ~ Ah, et tu as du café? ~ Oui j'en ai, mais j'en ai pas preparé…
D29: Oui j'en ai, mais j'en ai pas preparé… | F29: x2 | G29: =IF(F29="x",COUNTA($F$2:F29),".") -> . | H29: =IF(F29="x",D29,IF(AND(F29="x1",F30="x2",F31="x3"),"~ "&D29&CHAR(10)&"~ "&D30&CHAR(10)&"~ "&D31,IF(AND(F29="x1",F30="x2"),"~ "&D29&CHAR(10)&"~ "&D30,IF(AND(F29="x1",F30="x1'"),D29&" "&D30,"---")))) -> ---
C30: C'est pas grave | D30: C'est pas grave | F30: x | G30: =IF(F30="x",COUNTA($F$2:F30),".") -> 23 | H30: =IF(F30="x",D30,IF(AND(F30="x1",F31="x2",F32="x3"),"~ "&D30&CHAR(10)&"~ "&D31&CHAR(10)&"~ "&D32,IF(AND(F30="x1",F31="x2"),"~ "&D30&CHAR(10)&"~ "&D31,IF(AND(F30="x1",F31="x1'"),D30&" "&D31,"---")))) -> C'est pas grave
D31: Je dois aller voir au Louvre maintenant | E31: au = à + le | F31: x | G31: =IF(F31="x",COUNTA($F$2:F31),".") -> 24 | H31: =IF(F31="x",D31,IF(AND(F31="x1",F32="x2",F33="x3"),"~ "&D31&CHAR(10)&"~ "&D32&CHAR(10)&"~ "&D33,IF(AND(F31="x1",F32="x2"),"~ "&D31&CHAR(10)&"~ "&D32,IF(AND(F31="x1",F32="x1'"),D31&" "&D32,"---")))) -> Je dois aller voir au Louvre maintenant
D32: Je dois prendre un taxi | G32: =IF(F32="x",COUNTA($F$2:F32),".") -> . | H32: =IF(F32="x",D32,IF(AND(F32="x1",F33="x2",F34="x3"),"~ "&D32&CHAR(10)&"~ "&D33&CHAR(10)&"~ "&D34,IF(AND(F32="x1",F33="x2"),"~ "&D32&CHAR(10)&"~ "&D33,IF(AND(F32="x1",F33="x1'"),D32&" "&D33,"---")))) -> ---
C33: Où est-ce que | D33: Où est-ce que je peux prendre un taxi? | F33: x | G33: =IF(F33="x",COUNTA($F$2:F33),".") -> 25 | H33: =IF(F33="x",D33,IF(AND(F33="x1",F34="x2",F35="x3"),"~ "&D33&CHAR(10)&"~ "&D34&CHAR(10)&"~ "&D35,IF(AND(F33="x1",F34="x2"),"~ "&D33&CHAR(10)&"~ "&D34,IF(AND(F33="x1",F34="x1'"),D33&" "&D34,"---")))) -> Où est-ce que je peux prendre un taxi?
C34: Appeler | D34: Je peux appeler un taxi pour toi | F34: x1 | G34: =IF(F34="x",COUNTA($F$2:F34),".") -> . | H34: =IF(F34="x",D34,IF(AND(F34="x1",F35="x2",F36="x3"),"~ "&D34&CHAR(10)&"~ "&D35&CHAR(10)&"~ "&D36,IF(AND(F34="x1",F35="x2"),"~ "&D34&CHAR(10)&"~ "&D35,IF(AND(F34="x1",F35="x1'"),D34&" "&D35,"---")))) -> ~ Je peux appeler un taxi pour toi ~ Super, merci!
D35: Super, merci! | F35: x2 | G35: =IF(F35="x",COUNTA($F$2:F35),".") -> . | H35: =IF(F35="x",D35,IF(AND(F35="x1",F36="x2",F37="x3"),"~ "&D35&CHAR(10)&"~ "&D36&CHAR(10)&"~ "&D37,IF(AND(F35="x1",F36="x2"),"~ "&D35&CHAR(10)&"~ "&D36,IF(AND(F35="x1",F36="x1'"),D35&" "&D36,"---")))) -> ---
C36: 10 + minutes | D36: Tu dois attendre le taxi 10 minutes | F36: x | G36: =IF(F36="x",COUNTA($F$2:F36),".") -> 28 | H36: =IF(F36="x",D36,IF(AND(F36="x1",F37="x2",F38="x3"),"~ "&D36&CHAR(10)&"~ "&D37&CHAR(10)&"~ "&D38,IF(AND(F36="x1",F37="x2"),"~ "&D36&CHAR(10)&"~ "&D37,IF(AND(F36="x1",F37="x1'"),D36&" "&D37,"---")))) -> Tu dois attendre le taxi 10 minutes
C37: Combien? | D37: Ok, et c'est combien? | F37: x1 | G37: =IF(F37="x",COUNTA($F$2:F37),".") -> . | H37: =IF(F37="x",D37,IF(AND(F37="x1",F38="x2",F39="x3"),"~ "&D37&CHAR(10)&"~ "&D38&CHAR(10)&"~ "&D39,IF(AND(F37="x1",F38="x2"),"~ "&D37&CHAR(10)&"~ "&D38,IF(AND(F37="x1",F38="x1'"),D37&" "&D38,"---")))) -> ~ Ok, et c'est combien? ~ C'est 10 euros
C38: Euro | D38: C'est 10 euros | F38: x2 | G38: =IF(F38="x",COUNTA($F$2:F38),".") -> . | H38: =IF(F38="x",D38,IF(AND(F38="x1",F39="x2",F40="x3"),"~ "&D38&CHAR(10)&"~ "&D39&CHAR(10)&"~ "&D40,IF(AND(F38="x1",F39="x2"),"~ "&D38&CHAR(10)&"~ "&D39,IF(AND(F38="x1",F39="x1'"),D38&" "&D39,"---")))) -> ---
C39: Au revoir | D39: D'accord, au revoir! | F39: x1 | G39: =IF(F39="x",COUNTA($F$2:F39),".") -> . | H39: =IF(F39="x",D39,IF(AND(F39="x1",F40="x2",F41="x3"),"~ "&D39&CHAR(10)&"~ "&D40&CHAR(10)&"~ "&D42,IF(AND(F39="x1",F40="x2"),"~ "&D39&CHAR(10)&"~ "&D40,IF(AND(F39="x1",F40="x1'"),D39&" "&D40,"---")))) -> ~ D'accord, au revoir! ~ A plus tard!
C40: Plus tard | D40: A plus tard! | F40: x2 | G40: =COUNTA($F$2:F40) -> 32 | H40: =IF(F40="x",D40,IF(AND(F40="x1",F41="x2",F42="x3"),"~ "&D40&CHAR(10)&"~ "&D42&CHAR(10)&"~ "&D43,IF(AND(F40="x1",F41="x2"),"~ "&D40&CHAR(10)&"~ "&D42,IF(AND(F40="x1",F41="x1'"),D40&" "&D42,"---")))) -> ---
...

Sheet S10
A1: Type | B1: New Item | C1: Fr | D1: Notes | E1: Keep | F1: Cum.
A2: lesson title | C2: S10 - Paris 5 - En taxi vers Le Louvre | D2: Une amie te fait visiter Paris #5
A3: last | C3: A plus tard!
A4: Warm up
B16: Monsieur | C16: Bonjour Monsieur | F16: =IF(E16="x",COUNTA($E$2:E16),".") -> . | G16: =IF(E16="x",C16,IF(AND(E16="x1",E17="x2",E18="x3"),"~ "&C16&CHAR(10)&"~ "&C17&CHAR(10)&"~ "&C18,IF(AND(E16="x1",E17="x2"),"~ "&C16&CHAR(10)&"~ "&C17,IF(AND(E16="x1",E17="x1'"),C16&" "&C17,"---")))) -> ---
B17: Mademoiselle | C17: Bonjour Mademoiselle | F17: =IF(E17="x",COUNTA($E$2:E17),".") -> . | G17: =IF(E17="x",C17,IF(AND(E17="x1",E18="x2",E19="x3"),"~ "&C17&CHAR(10)&"~ "&C18&CHAR(10)&"~ "&C19,IF(AND(E17="x1",E18="x2"),"~ "&C17&CHAR(10)&"~ "&C18,IF(AND(E17="x1",E18="x1'"),C17&" "&C18,"---")))) -> ---
B18: apres | C18: Je dois payer maintenant ou apres? | F18: =IF(E18="x",COUNTA($E$2:E18),".") -> . | G18: =IF(E18="x",C18,IF(AND(E18="x1",E19="x2",E20="x3"),"~ "&C18&CHAR(10)&"~ "&C19&CHAR(10)&"~ "&C20,IF(AND(E18="x1",E19="x2"),"~ "&C18&CHAR(10)&"~ "&C19,IF(AND(E18="x1",E19="x1'"),C18&" "&C19,"---")))) -> ---
B19: tout a l'heure | C19: Vous pouvez payer tout 0 l'heure | F19: =IF(E19="x",COUNTA($E$2:E19),".") -> . | G19: =IF(E19="x",C19,IF(AND(E19="x1",E20="x2",E21="x3"),"~ "&C19&CHAR(10)&"~ "&C20&CHAR(10)&"~ "&C21,IF(AND(E19="x1",E20="x2"),"~ "&C19&CHAR(10)&"~ "&C20,IF(AND(E19="x1",E20="x1'"),C19&" "&C20,"---")))) -> ---
B20: rentrer | C20: Vous voulez aller au Louvre, c'est ca? | D20: drill voulez + voulons | F20: =IF(E20="x",COUNTA($E$2:E20),".") -> . | G20: =IF(E20="x",C20,IF(AND(E20="x1",E21="x2",E22="x3"),"~ "&C20&CHAR(10)&"~ "&C21&CHAR(10)&"~ "&C22,IF(AND(E20="x1",E21="x2"),"~ "&C20&CHAR(10)&"~ "&C21,IF(AND(E20="x1",E21="x1'"),C20&" "&C21,"---")))) -> ---
